(0.000) SELECT "django_session"."session_key", "django_session"."session_data", "django_session"."expire_date" FROM "django_session" WHERE ("django_session"."expire_date" > '2024-07-29T16:36:54.792344+00:00'::timestamptz AND "django_session"."session_key" = '3p1d4dpf1cga1qzicy5fnkqyjv7p6t0s') LIMIT 21; args=(datetime.datetime(2024, 7, 29, 16, 36, 54, 792344, tzinfo=datetime.timezone.utc), '3p1d4dpf1cga1qzicy5fnkqyjv7p6t0s'); alias=default
(0.000) SELECT "auth_user"."id", "auth_user"."password", "auth_user"."last_login", "auth_user"."is_superuser", "auth_user"."username", "auth_user"."first_name", "auth_user"."last_name", "auth_user"."email", "auth_user"."is_staff", "auth_user"."is_active", "auth_user"."date_joined" FROM "auth_user" WHERE "auth_user"."id" = 1 LIMIT 21; args=(1,); alias=default
"GET /sh/device/list/ HTTP/1.1" 200 13081
"GET /static/lib/fontawesome_6.5.2/css/all.min.css HTTP/1.1" 200 103009
"GET /static/lib/adminlte_3.2.0/plugins/jquery/jquery.min.js HTTP/1.1" 200 89501
"GET /static/lib/adminlte_3.2.0/plugins/datatables-bs4/css/dataTables.bootstrap4.min.css HTTP/1.1" 200 7496
"GET /static/css/styles.css HTTP/1.1" 200 442
"GET /static/lib/jquery-confirm-v3.3.4/jquery-confirm.min.css HTTP/1.1" 200 22546
"GET /static/device/js/list.js HTTP/1.1" 200 1357
"GET /static/img/sh_logo.svg HTTP/1.1" 200 592
"GET /static/lib/adminlte_3.2.0/dist/img/user2-160x160.jpg HTTP/1.1" 200 6905
"GET /static/lib/adminlte_3.2.0/plugins/datatables/jquery.dataTables.min.js HTTP/1.1" 200 87956
"GET /static/lib/adminlte_3.2.0/dist/js/adminlte.min.js HTTP/1.1" 200 46369
"GET /static/lib/adminlte_3.2.0/dist/css/adminlte.min.css HTTP/1.1" 200 1396747
"GET /static/lib/sweetalert2-11.11.0/sweetalert2.all.min.js HTTP/1.1" 200 76213
"GET /static/lib/fontawesome_6.5.2/js/all.min.js HTTP/1.1" 200 1489225
"GET /static/lib/jquery-confirm-v3.3.4/jquery-confirm.min.js HTTP/1.1" 200 28231
"GET /static/js/functions.js HTTP/1.1" 200 2429
"GET /static/lib/adminlte_3.2.0/plugins/datatables-bs4/js/dataTables.bootstrap4.min.js HTTP/1.1" 200 4520
"GET /static/lib/fontawesome_6.5.2/webfonts/fa-solid-900.woff2 HTTP/1.1" 200 156400
Exception while resolving variable 'name' in template 'unknown'.
Traceback (most recent call last):
  File "D:\TRABAJO\Desarrollo\control_equipos\env\Lib\site-packages\django\core\handlers\exception.py", line 55, in inner
    response = get_response(request)
               ^^^^^^^^^^^^^^^^^^^^^
  File "D:\TRABAJO\Desarrollo\control_equipos\env\Lib\site-packages\django\core\handlers\base.py", line 181, in _get_response
    callback, callback_args, callback_kwargs = self.resolve_request(request)
                                               ^^^^^^^^^^^^^^^^^^^^^^^^^^^^^
  File "D:\TRABAJO\Desarrollo\control_equipos\env\Lib\site-packages\django\core\handlers\base.py", line 313, in resolve_request
    resolver_match = resolver.resolve(request.path_info)
                     ^^^^^^^^^^^^^^^^^^^^^^^^^^^^^^^^^^^
  File "D:\TRABAJO\Desarrollo\control_equipos\env\Lib\site-packages\django\urls\resolvers.py", line 725, in resolve
    raise Resolver404({"tried": tried, "path": new_path})
django.urls.exceptions.Resolver404: {'tried': [[<URLPattern '' [name='index']>], [<URLResolver <module 'core.login.urls' from 'D:\\TRABAJO\\Desarrollo\\control_equipos\\smartHunt\\core\\login\\urls.py'> (None:None) 'login/'>], [<URLResolver <URLPattern list> (admin:admin) 'admin/'>], [<URLResolver <module 'core.sh.urls' from 'D:\\TRABAJO\\Desarrollo\\control_equipos\\smartHunt\\core\\sh\\urls.py'> (sh:sh) 'sh/'>], [<URLPattern '^media/(?P<path>.*)$'>]], 'path': 'favicon.ico'}

During handling of the above exception, another exception occurred:

Traceback (most recent call last):
  File "D:\TRABAJO\Desarrollo\control_equipos\env\Lib\site-packages\django\template\base.py", line 875, in _resolve_lookup
    current = current[bit]
              ~~~~~~~^^^^^
TypeError: 'URLResolver' object is not subscriptable

During handling of the above exception, another exception occurred:

Traceback (most recent call last):
  File "D:\TRABAJO\Desarrollo\control_equipos\env\Lib\site-packages\django\template\base.py", line 885, in _resolve_lookup
    current = getattr(current, bit)
              ^^^^^^^^^^^^^^^^^^^^^
AttributeError: 'URLResolver' object has no attribute 'name'

During handling of the above exception, another exception occurred:

Traceback (most recent call last):
  File "D:\TRABAJO\Desarrollo\control_equipos\env\Lib\site-packages\django\template\base.py", line 891, in _resolve_lookup
    current = current[int(bit)]
                      ^^^^^^^^
ValueError: invalid literal for int() with base 10: 'name'

During handling of the above exception, another exception occurred:

Traceback (most recent call last):
  File "D:\TRABAJO\Desarrollo\control_equipos\env\Lib\site-packages\django\template\base.py", line 898, in _resolve_lookup
    raise VariableDoesNotExist(
django.template.base.VariableDoesNotExist: Failed lookup for key [name] in <URLResolver <module 'core.login.urls' from 'D:\\TRABAJO\\Desarrollo\\control_equipos\\smartHunt\\core\\login\\urls.py'> (None:None) 'login/'>
Exception while resolving variable 'name' in template 'unknown'.
Traceback (most recent call last):
  File "D:\TRABAJO\Desarrollo\control_equipos\env\Lib\site-packages\django\core\handlers\exception.py", line 55, in inner
    response = get_response(request)
               ^^^^^^^^^^^^^^^^^^^^^
  File "D:\TRABAJO\Desarrollo\control_equipos\env\Lib\site-packages\django\core\handlers\base.py", line 181, in _get_response
    callback, callback_args, callback_kwargs = self.resolve_request(request)
                                               ^^^^^^^^^^^^^^^^^^^^^^^^^^^^^
  File "D:\TRABAJO\Desarrollo\control_equipos\env\Lib\site-packages\django\core\handlers\base.py", line 313, in resolve_request
    resolver_match = resolver.resolve(request.path_info)
                     ^^^^^^^^^^^^^^^^^^^^^^^^^^^^^^^^^^^
  File "D:\TRABAJO\Desarrollo\control_equipos\env\Lib\site-packages\django\urls\resolvers.py", line 725, in resolve
    raise Resolver404({"tried": tried, "path": new_path})
django.urls.exceptions.Resolver404: {'tried': [[<URLPattern '' [name='index']>], [<URLResolver <module 'core.login.urls' from 'D:\\TRABAJO\\Desarrollo\\control_equipos\\smartHunt\\core\\login\\urls.py'> (None:None) 'login/'>], [<URLResolver <URLPattern list> (admin:admin) 'admin/'>], [<URLResolver <module 'core.sh.urls' from 'D:\\TRABAJO\\Desarrollo\\control_equipos\\smartHunt\\core\\sh\\urls.py'> (sh:sh) 'sh/'>], [<URLPattern '^media/(?P<path>.*)$'>]], 'path': 'favicon.ico'}

During handling of the above exception, another exception occurred:

Traceback (most recent call last):
  File "D:\TRABAJO\Desarrollo\control_equipos\env\Lib\site-packages\django\template\base.py", line 875, in _resolve_lookup
    current = current[bit]
              ~~~~~~~^^^^^
TypeError: 'URLResolver' object is not subscriptable

During handling of the above exception, another exception occurred:

Traceback (most recent call last):
  File "D:\TRABAJO\Desarrollo\control_equipos\env\Lib\site-packages\django\template\base.py", line 885, in _resolve_lookup
    current = getattr(current, bit)
              ^^^^^^^^^^^^^^^^^^^^^
AttributeError: 'URLResolver' object has no attribute 'name'

During handling of the above exception, another exception occurred:

Traceback (most recent call last):
  File "D:\TRABAJO\Desarrollo\control_equipos\env\Lib\site-packages\django\template\base.py", line 891, in _resolve_lookup
    current = current[int(bit)]
                      ^^^^^^^^
ValueError: invalid literal for int() with base 10: 'name'

During handling of the above exception, another exception occurred:

Traceback (most recent call last):
  File "D:\TRABAJO\Desarrollo\control_equipos\env\Lib\site-packages\django\template\base.py", line 898, in _resolve_lookup
    raise VariableDoesNotExist(
django.template.base.VariableDoesNotExist: Failed lookup for key [name] in <URLResolver <URLPattern list> (admin:admin) 'admin/'>
Exception while resolving variable 'name' in template 'unknown'.
Traceback (most recent call last):
  File "D:\TRABAJO\Desarrollo\control_equipos\env\Lib\site-packages\django\core\handlers\exception.py", line 55, in inner
    response = get_response(request)
               ^^^^^^^^^^^^^^^^^^^^^
  File "D:\TRABAJO\Desarrollo\control_equipos\env\Lib\site-packages\django\core\handlers\base.py", line 181, in _get_response
    callback, callback_args, callback_kwargs = self.resolve_request(request)
                                               ^^^^^^^^^^^^^^^^^^^^^^^^^^^^^
  File "D:\TRABAJO\Desarrollo\control_equipos\env\Lib\site-packages\django\core\handlers\base.py", line 313, in resolve_request
    resolver_match = resolver.resolve(request.path_info)
                     ^^^^^^^^^^^^^^^^^^^^^^^^^^^^^^^^^^^
  File "D:\TRABAJO\Desarrollo\control_equipos\env\Lib\site-packages\django\urls\resolvers.py", line 725, in resolve
    raise Resolver404({"tried": tried, "path": new_path})
django.urls.exceptions.Resolver404: {'tried': [[<URLPattern '' [name='index']>], [<URLResolver <module 'core.login.urls' from 'D:\\TRABAJO\\Desarrollo\\control_equipos\\smartHunt\\core\\login\\urls.py'> (None:None) 'login/'>], [<URLResolver <URLPattern list> (admin:admin) 'admin/'>], [<URLResolver <module 'core.sh.urls' from 'D:\\TRABAJO\\Desarrollo\\control_equipos\\smartHunt\\core\\sh\\urls.py'> (sh:sh) 'sh/'>], [<URLPattern '^media/(?P<path>.*)$'>]], 'path': 'favicon.ico'}

During handling of the above exception, another exception occurred:

Traceback (most recent call last):
  File "D:\TRABAJO\Desarrollo\control_equipos\env\Lib\site-packages\django\template\base.py", line 875, in _resolve_lookup
    current = current[bit]
              ~~~~~~~^^^^^
TypeError: 'URLResolver' object is not subscriptable

During handling of the above exception, another exception occurred:

Traceback (most recent call last):
  File "D:\TRABAJO\Desarrollo\control_equipos\env\Lib\site-packages\django\template\base.py", line 885, in _resolve_lookup
    current = getattr(current, bit)
              ^^^^^^^^^^^^^^^^^^^^^
AttributeError: 'URLResolver' object has no attribute 'name'

During handling of the above exception, another exception occurred:

Traceback (most recent call last):
  File "D:\TRABAJO\Desarrollo\control_equipos\env\Lib\site-packages\django\template\base.py", line 891, in _resolve_lookup
    current = current[int(bit)]
                      ^^^^^^^^
ValueError: invalid literal for int() with base 10: 'name'

During handling of the above exception, another exception occurred:

Traceback (most recent call last):
  File "D:\TRABAJO\Desarrollo\control_equipos\env\Lib\site-packages\django\template\base.py", line 898, in _resolve_lookup
    raise VariableDoesNotExist(
django.template.base.VariableDoesNotExist: Failed lookup for key [name] in <URLResolver <module 'core.sh.urls' from 'D:\\TRABAJO\\Desarrollo\\control_equipos\\smartHunt\\core\\sh\\urls.py'> (sh:sh) 'sh/'>
Not Found: /favicon.ico
"GET /favicon.ico HTTP/1.1" 404 2559
(0.000) SELECT "django_session"."session_key", "django_session"."session_data", "django_session"."expire_date" FROM "django_session" WHERE ("django_session"."expire_date" > '2024-07-29T16:36:55.126272+00:00'::timestamptz AND "django_session"."session_key" = '3p1d4dpf1cga1qzicy5fnkqyjv7p6t0s') LIMIT 21; args=(datetime.datetime(2024, 7, 29, 16, 36, 55, 126272, tzinfo=datetime.timezone.utc), '3p1d4dpf1cga1qzicy5fnkqyjv7p6t0s'); alias=default
(0.000) SELECT "auth_user"."id", "auth_user"."password", "auth_user"."last_login", "auth_user"."is_superuser", "auth_user"."username", "auth_user"."first_name", "auth_user"."last_name", "auth_user"."email", "auth_user"."is_staff", "auth_user"."is_active", "auth_user"."date_joined" FROM "auth_user" WHERE "auth_user"."id" = 1 LIMIT 21; args=(1,); alias=default
(0.016) SELECT "dispositivos"."id", "dispositivos"."dev_model_id", "dispositivos"."connection_type_id", "dispositivos"."ip", "dispositivos"."dev_net_name", "dispositivos"."dev_status_id", "dispositivos"."serial_number", "dispositivos"."wall_port_id", "dispositivos"."switch_port_id", "dispositivos"."date_creation", "dispositivos"."date_updated" FROM "dispositivos" ORDER BY "dispositivos"."id" ASC; args=(); alias=default
(0.000) SELECT "empleados"."id", "empleados"."employee_name", "empleados"."employee_last_name", "empleados"."cuil", "empleados"."status_id", "empleados"."user_pc", "empleados"."office_id", "empleados"."avatar", "empleados"."date_creation", "empleados"."date_updated" FROM "empleados" INNER JOIN "dispositivos_employee" ON ("empleados"."id" = "dispositivos_employee"."employee_id") WHERE "dispositivos_employee"."device_id" = 2 ORDER BY "empleados"."id" ASC; args=(2,); alias=default
(0.000) SELECT "modelo"."id", "modelo"."dev_type_id", "modelo"."brand_id", "modelo"."dev_model", "modelo"."image", "modelo"."date_creation", "modelo"."date_updated" FROM "modelo" WHERE "modelo"."id" = 2 LIMIT 21; args=(2,); alias=default
(0.000) SELECT "tipo_de_dispositivo"."id", "tipo_de_dispositivo"."dev_type", "tipo_de_dispositivo"."date_creation", "tipo_de_dispositivo"."date_updated" FROM "tipo_de_dispositivo" WHERE "tipo_de_dispositivo"."id" = 2 LIMIT 21; args=(2,); alias=default
(0.000) SELECT "estado_del_dispositivo"."id", "estado_del_dispositivo"."dev_status", "estado_del_dispositivo"."date_creation", "estado_del_dispositivo"."date_updated" FROM "estado_del_dispositivo" WHERE "estado_del_dispositivo"."id" = 1 LIMIT 21; args=(1,); alias=default
(0.000) SELECT 1 AS "a" FROM "empleados" INNER JOIN "dispositivos_employee" ON ("empleados"."id" = "dispositivos_employee"."employee_id") WHERE "dispositivos_employee"."device_id" = 2 LIMIT 1; args=(1, 2); alias=default
(0.000) SELECT "empleados"."id", "empleados"."employee_name", "empleados"."employee_last_name", "empleados"."cuil", "empleados"."status_id", "empleados"."user_pc", "empleados"."office_id", "empleados"."avatar", "empleados"."date_creation", "empleados"."date_updated" FROM "empleados" INNER JOIN "dispositivos_employee" ON ("empleados"."id" = "dispositivos_employee"."employee_id") WHERE "dispositivos_employee"."device_id" = 2 ORDER BY "empleados"."id" ASC LIMIT 1; args=(2,); alias=default
(0.000) SELECT "oficina"."id", "oficina"."dependency_id", "oficina"."office", "oficina"."date_creation", "oficina"."date_updated" FROM "oficina" WHERE "oficina"."id" = 1 LIMIT 21; args=(1,); alias=default
Internal Server Error: /sh/device/list/
"POST /sh/device/list/ HTTP/1.1" 500 52
File D:\TRABAJO\Desarrollo\control_equipos\env\Lib\site-packages\django\contrib\messages\storage\fallback.py first seen with mtime 1715779757.173412
File D:\TRABAJO\Desarrollo\control_equipos\env\Lib\site-packages\django\contrib\messages\storage\session.py first seen with mtime 1715779757.1744037
File D:\TRABAJO\Desarrollo\control_equipos\env\Lib\site-packages\django\template\context_processors.py first seen with mtime 1715779757.5948129
File D:\TRABAJO\Desarrollo\control_equipos\env\Lib\site-packages\django\contrib\auth\context_processors.py first seen with mtime 1715779756.741706
File D:\TRABAJO\Desarrollo\control_equipos\env\Lib\site-packages\django\contrib\sessions\serializers.py first seen with mtime 1715779757.3079624
File D:\TRABAJO\Desarrollo\control_equipos\env\Lib\site-packages\django\contrib\messages\storage\cookie.py first seen with mtime 1715779757.173412
File D:\TRABAJO\Desarrollo\control_equipos\env\Lib\site-packages\django\contrib\staticfiles\storage.py first seen with mtime 1715779757.4798193
File D:\TRABAJO\Desarrollo\control_equipos\env\Lib\site-packages\django\contrib\messages\context_processors.py first seen with mtime 1715779757.1713312
(0.000) SELECT "django_session"."session_key", "django_session"."session_data", "django_session"."expire_date" FROM "django_session" WHERE ("django_session"."expire_date" > '2024-07-29T16:40:32.931727+00:00'::timestamptz AND "django_session"."session_key" = '3p1d4dpf1cga1qzicy5fnkqyjv7p6t0s') LIMIT 21; args=(datetime.datetime(2024, 7, 29, 16, 40, 32, 931727, tzinfo=datetime.timezone.utc), '3p1d4dpf1cga1qzicy5fnkqyjv7p6t0s'); alias=default
(0.000) SELECT "auth_user"."id", "auth_user"."password", "auth_user"."last_login", "auth_user"."is_superuser", "auth_user"."username", "auth_user"."first_name", "auth_user"."last_name", "auth_user"."email", "auth_user"."is_staff", "auth_user"."is_active", "auth_user"."date_joined" FROM "auth_user" WHERE "auth_user"."id" = 1 LIMIT 21; args=(1,); alias=default
"GET /sh/device/list/ HTTP/1.1" 200 13081
"GET /static/css/styles.css HTTP/1.1" 200 442
"GET /static/lib/jquery-confirm-v3.3.4/jquery-confirm.min.css HTTP/1.1" 200 22546
"GET /static/lib/adminlte_3.2.0/plugins/jquery/jquery.min.js HTTP/1.1" 200 89501
"GET /static/lib/adminlte_3.2.0/plugins/datatables-bs4/css/dataTables.bootstrap4.min.css HTTP/1.1" 200 7496
"GET /static/lib/adminlte_3.2.0/plugins/datatables/jquery.dataTables.min.js HTTP/1.1" 200 87956
"GET /static/lib/fontawesome_6.5.2/css/all.min.css HTTP/1.1" 200 103009
"GET /static/device/js/list.js HTTP/1.1" 200 1359
"GET /static/img/sh_logo.svg HTTP/1.1" 200 592
"GET /static/lib/adminlte_3.2.0/dist/img/user2-160x160.jpg HTTP/1.1" 200 6905
"GET /static/lib/adminlte_3.2.0/dist/css/adminlte.min.css HTTP/1.1" 200 1396747
"GET /static/lib/adminlte_3.2.0/dist/js/adminlte.min.js HTTP/1.1" 200 46369
"GET /static/lib/fontawesome_6.5.2/js/all.min.js HTTP/1.1" 200 1489225
"GET /static/lib/jquery-confirm-v3.3.4/jquery-confirm.min.js HTTP/1.1" 200 28231
"GET /static/lib/sweetalert2-11.11.0/sweetalert2.all.min.js HTTP/1.1" 200 76213
"GET /static/lib/adminlte_3.2.0/plugins/datatables-bs4/js/dataTables.bootstrap4.min.js HTTP/1.1" 200 4520
"GET /static/js/functions.js HTTP/1.1" 200 2429
"GET /static/lib/fontawesome_6.5.2/webfonts/fa-solid-900.woff2 HTTP/1.1" 200 156400
Exception while resolving variable 'name' in template 'unknown'.
Traceback (most recent call last):
  File "D:\TRABAJO\Desarrollo\control_equipos\env\Lib\site-packages\django\core\handlers\exception.py", line 55, in inner
    response = get_response(request)
               ^^^^^^^^^^^^^^^^^^^^^
  File "D:\TRABAJO\Desarrollo\control_equipos\env\Lib\site-packages\django\core\handlers\base.py", line 181, in _get_response
    callback, callback_args, callback_kwargs = self.resolve_request(request)
                                               ^^^^^^^^^^^^^^^^^^^^^^^^^^^^^
  File "D:\TRABAJO\Desarrollo\control_equipos\env\Lib\site-packages\django\core\handlers\base.py", line 313, in resolve_request
    resolver_match = resolver.resolve(request.path_info)
                     ^^^^^^^^^^^^^^^^^^^^^^^^^^^^^^^^^^^
  File "D:\TRABAJO\Desarrollo\control_equipos\env\Lib\site-packages\django\urls\resolvers.py", line 725, in resolve
    raise Resolver404({"tried": tried, "path": new_path})
django.urls.exceptions.Resolver404: {'tried': [[<URLPattern '' [name='index']>], [<URLResolver <module 'core.login.urls' from 'D:\\TRABAJO\\Desarrollo\\control_equipos\\smartHunt\\core\\login\\urls.py'> (None:None) 'login/'>], [<URLResolver <URLPattern list> (admin:admin) 'admin/'>], [<URLResolver <module 'core.sh.urls' from 'D:\\TRABAJO\\Desarrollo\\control_equipos\\smartHunt\\core\\sh\\urls.py'> (sh:sh) 'sh/'>], [<URLPattern '^media/(?P<path>.*)$'>]], 'path': 'favicon.ico'}

During handling of the above exception, another exception occurred:

Traceback (most recent call last):
  File "D:\TRABAJO\Desarrollo\control_equipos\env\Lib\site-packages\django\template\base.py", line 875, in _resolve_lookup
    current = current[bit]
              ~~~~~~~^^^^^
TypeError: 'URLResolver' object is not subscriptable

During handling of the above exception, another exception occurred:

Traceback (most recent call last):
  File "D:\TRABAJO\Desarrollo\control_equipos\env\Lib\site-packages\django\template\base.py", line 885, in _resolve_lookup
    current = getattr(current, bit)
              ^^^^^^^^^^^^^^^^^^^^^
AttributeError: 'URLResolver' object has no attribute 'name'

During handling of the above exception, another exception occurred:

Traceback (most recent call last):
  File "D:\TRABAJO\Desarrollo\control_equipos\env\Lib\site-packages\django\template\base.py", line 891, in _resolve_lookup
    current = current[int(bit)]
                      ^^^^^^^^
ValueError: invalid literal for int() with base 10: 'name'

During handling of the above exception, another exception occurred:

Traceback (most recent call last):
  File "D:\TRABAJO\Desarrollo\control_equipos\env\Lib\site-packages\django\template\base.py", line 898, in _resolve_lookup
    raise VariableDoesNotExist(
django.template.base.VariableDoesNotExist: Failed lookup for key [name] in <URLResolver <module 'core.login.urls' from 'D:\\TRABAJO\\Desarrollo\\control_equipos\\smartHunt\\core\\login\\urls.py'> (None:None) 'login/'>
Exception while resolving variable 'name' in template 'unknown'.
Traceback (most recent call last):
  File "D:\TRABAJO\Desarrollo\control_equipos\env\Lib\site-packages\django\core\handlers\exception.py", line 55, in inner
    response = get_response(request)
               ^^^^^^^^^^^^^^^^^^^^^
  File "D:\TRABAJO\Desarrollo\control_equipos\env\Lib\site-packages\django\core\handlers\base.py", line 181, in _get_response
    callback, callback_args, callback_kwargs = self.resolve_request(request)
                                               ^^^^^^^^^^^^^^^^^^^^^^^^^^^^^
  File "D:\TRABAJO\Desarrollo\control_equipos\env\Lib\site-packages\django\core\handlers\base.py", line 313, in resolve_request
    resolver_match = resolver.resolve(request.path_info)
                     ^^^^^^^^^^^^^^^^^^^^^^^^^^^^^^^^^^^
  File "D:\TRABAJO\Desarrollo\control_equipos\env\Lib\site-packages\django\urls\resolvers.py", line 725, in resolve
    raise Resolver404({"tried": tried, "path": new_path})
django.urls.exceptions.Resolver404: {'tried': [[<URLPattern '' [name='index']>], [<URLResolver <module 'core.login.urls' from 'D:\\TRABAJO\\Desarrollo\\control_equipos\\smartHunt\\core\\login\\urls.py'> (None:None) 'login/'>], [<URLResolver <URLPattern list> (admin:admin) 'admin/'>], [<URLResolver <module 'core.sh.urls' from 'D:\\TRABAJO\\Desarrollo\\control_equipos\\smartHunt\\core\\sh\\urls.py'> (sh:sh) 'sh/'>], [<URLPattern '^media/(?P<path>.*)$'>]], 'path': 'favicon.ico'}

During handling of the above exception, another exception occurred:

Traceback (most recent call last):
  File "D:\TRABAJO\Desarrollo\control_equipos\env\Lib\site-packages\django\template\base.py", line 875, in _resolve_lookup
    current = current[bit]
              ~~~~~~~^^^^^
TypeError: 'URLResolver' object is not subscriptable

During handling of the above exception, another exception occurred:

Traceback (most recent call last):
  File "D:\TRABAJO\Desarrollo\control_equipos\env\Lib\site-packages\django\template\base.py", line 885, in _resolve_lookup
    current = getattr(current, bit)
              ^^^^^^^^^^^^^^^^^^^^^
AttributeError: 'URLResolver' object has no attribute 'name'

During handling of the above exception, another exception occurred:

Traceback (most recent call last):
  File "D:\TRABAJO\Desarrollo\control_equipos\env\Lib\site-packages\django\template\base.py", line 891, in _resolve_lookup
    current = current[int(bit)]
                      ^^^^^^^^
ValueError: invalid literal for int() with base 10: 'name'

During handling of the above exception, another exception occurred:

Traceback (most recent call last):
  File "D:\TRABAJO\Desarrollo\control_equipos\env\Lib\site-packages\django\template\base.py", line 898, in _resolve_lookup
    raise VariableDoesNotExist(
django.template.base.VariableDoesNotExist: Failed lookup for key [name] in <URLResolver <URLPattern list> (admin:admin) 'admin/'>
Exception while resolving variable 'name' in template 'unknown'.
Traceback (most recent call last):
  File "D:\TRABAJO\Desarrollo\control_equipos\env\Lib\site-packages\django\core\handlers\exception.py", line 55, in inner
    response = get_response(request)
               ^^^^^^^^^^^^^^^^^^^^^
  File "D:\TRABAJO\Desarrollo\control_equipos\env\Lib\site-packages\django\core\handlers\base.py", line 181, in _get_response
    callback, callback_args, callback_kwargs = self.resolve_request(request)
                                               ^^^^^^^^^^^^^^^^^^^^^^^^^^^^^
  File "D:\TRABAJO\Desarrollo\control_equipos\env\Lib\site-packages\django\core\handlers\base.py", line 313, in resolve_request
    resolver_match = resolver.resolve(request.path_info)
                     ^^^^^^^^^^^^^^^^^^^^^^^^^^^^^^^^^^^
  File "D:\TRABAJO\Desarrollo\control_equipos\env\Lib\site-packages\django\urls\resolvers.py", line 725, in resolve
    raise Resolver404({"tried": tried, "path": new_path})
django.urls.exceptions.Resolver404: {'tried': [[<URLPattern '' [name='index']>], [<URLResolver <module 'core.login.urls' from 'D:\\TRABAJO\\Desarrollo\\control_equipos\\smartHunt\\core\\login\\urls.py'> (None:None) 'login/'>], [<URLResolver <URLPattern list> (admin:admin) 'admin/'>], [<URLResolver <module 'core.sh.urls' from 'D:\\TRABAJO\\Desarrollo\\control_equipos\\smartHunt\\core\\sh\\urls.py'> (sh:sh) 'sh/'>], [<URLPattern '^media/(?P<path>.*)$'>]], 'path': 'favicon.ico'}

During handling of the above exception, another exception occurred:

Traceback (most recent call last):
  File "D:\TRABAJO\Desarrollo\control_equipos\env\Lib\site-packages\django\template\base.py", line 875, in _resolve_lookup
    current = current[bit]
              ~~~~~~~^^^^^
TypeError: 'URLResolver' object is not subscriptable

During handling of the above exception, another exception occurred:

Traceback (most recent call last):
  File "D:\TRABAJO\Desarrollo\control_equipos\env\Lib\site-packages\django\template\base.py", line 885, in _resolve_lookup
    current = getattr(current, bit)
              ^^^^^^^^^^^^^^^^^^^^^
AttributeError: 'URLResolver' object has no attribute 'name'

During handling of the above exception, another exception occurred:

Traceback (most recent call last):
  File "D:\TRABAJO\Desarrollo\control_equipos\env\Lib\site-packages\django\template\base.py", line 891, in _resolve_lookup
    current = current[int(bit)]
                      ^^^^^^^^
ValueError: invalid literal for int() with base 10: 'name'

During handling of the above exception, another exception occurred:

Traceback (most recent call last):
  File "D:\TRABAJO\Desarrollo\control_equipos\env\Lib\site-packages\django\template\base.py", line 898, in _resolve_lookup
    raise VariableDoesNotExist(
django.template.base.VariableDoesNotExist: Failed lookup for key [name] in <URLResolver <module 'core.sh.urls' from 'D:\\TRABAJO\\Desarrollo\\control_equipos\\smartHunt\\core\\sh\\urls.py'> (sh:sh) 'sh/'>
Not Found: /favicon.ico
"GET /favicon.ico HTTP/1.1" 404 2559
(0.000) SELECT "django_session"."session_key", "django_session"."session_data", "django_session"."expire_date" FROM "django_session" WHERE ("django_session"."expire_date" > '2024-07-29T16:40:33.131638+00:00'::timestamptz AND "django_session"."session_key" = '3p1d4dpf1cga1qzicy5fnkqyjv7p6t0s') LIMIT 21; args=(datetime.datetime(2024, 7, 29, 16, 40, 33, 131638, tzinfo=datetime.timezone.utc), '3p1d4dpf1cga1qzicy5fnkqyjv7p6t0s'); alias=default
(0.000) SELECT "auth_user"."id", "auth_user"."password", "auth_user"."last_login", "auth_user"."is_superuser", "auth_user"."username", "auth_user"."first_name", "auth_user"."last_name", "auth_user"."email", "auth_user"."is_staff", "auth_user"."is_active", "auth_user"."date_joined" FROM "auth_user" WHERE "auth_user"."id" = 1 LIMIT 21; args=(1,); alias=default
(0.016) SELECT "dispositivos"."id", "dispositivos"."dev_model_id", "dispositivos"."connection_type_id", "dispositivos"."ip", "dispositivos"."dev_net_name", "dispositivos"."dev_status_id", "dispositivos"."serial_number", "dispositivos"."wall_port_id", "dispositivos"."switch_port_id", "dispositivos"."date_creation", "dispositivos"."date_updated" FROM "dispositivos" ORDER BY "dispositivos"."id" ASC; args=(); alias=default
(0.000) SELECT "empleados"."id", "empleados"."employee_name", "empleados"."employee_last_name", "empleados"."cuil", "empleados"."status_id", "empleados"."user_pc", "empleados"."office_id", "empleados"."avatar", "empleados"."date_creation", "empleados"."date_updated" FROM "empleados" INNER JOIN "dispositivos_employee" ON ("empleados"."id" = "dispositivos_employee"."employee_id") WHERE "dispositivos_employee"."device_id" = 2 ORDER BY "empleados"."id" ASC; args=(2,); alias=default
(0.000) SELECT "modelo"."id", "modelo"."dev_type_id", "modelo"."brand_id", "modelo"."dev_model", "modelo"."image", "modelo"."date_creation", "modelo"."date_updated" FROM "modelo" WHERE "modelo"."id" = 2 LIMIT 21; args=(2,); alias=default
(0.000) SELECT "tipo_de_dispositivo"."id", "tipo_de_dispositivo"."dev_type", "tipo_de_dispositivo"."date_creation", "tipo_de_dispositivo"."date_updated" FROM "tipo_de_dispositivo" WHERE "tipo_de_dispositivo"."id" = 2 LIMIT 21; args=(2,); alias=default
(0.000) SELECT "estado_del_dispositivo"."id", "estado_del_dispositivo"."dev_status", "estado_del_dispositivo"."date_creation", "estado_del_dispositivo"."date_updated" FROM "estado_del_dispositivo" WHERE "estado_del_dispositivo"."id" = 1 LIMIT 21; args=(1,); alias=default
(0.000) SELECT 1 AS "a" FROM "empleados" INNER JOIN "dispositivos_employee" ON ("empleados"."id" = "dispositivos_employee"."employee_id") WHERE "dispositivos_employee"."device_id" = 2 LIMIT 1; args=(1, 2); alias=default
(0.000) SELECT "empleados"."id", "empleados"."employee_name", "empleados"."employee_last_name", "empleados"."cuil", "empleados"."status_id", "empleados"."user_pc", "empleados"."office_id", "empleados"."avatar", "empleados"."date_creation", "empleados"."date_updated" FROM "empleados" INNER JOIN "dispositivos_employee" ON ("empleados"."id" = "dispositivos_employee"."employee_id") WHERE "dispositivos_employee"."device_id" = 2 ORDER BY "empleados"."id" ASC LIMIT 1; args=(2,); alias=default
(0.000) SELECT "oficina"."id", "oficina"."dependency_id", "oficina"."office", "oficina"."date_creation", "oficina"."date_updated" FROM "oficina" WHERE "oficina"."id" = 1 LIMIT 21; args=(1,); alias=default
Internal Server Error: /sh/device/list/
"POST /sh/device/list/ HTTP/1.1" 500 52
